<robot name="ers6">
  <link name="world"></link>
  <joint name="base_joint" type="fixed">
    <parent link="world" />
    <child link="base_link" />
    <origin xyz="0 0 0" rpy="0 0 0" />
  </joint>
  <link name="base_link">
    <visual>
      <origin xyz="0 0 0" rpy="0 0 0" />
      <geometry>
        <mesh filename="package://ers6_description/meshes/Base.stl" scale="0.001 0.001 0.001" />
      </geometry>
      <material name="base_link-material">
        <color rgba="0.07618538147321911 0.00030352698352941176 0.36130677977297226 1" />
      </material>
    </visual>
    <collision>
      <origin xyz="0 0 0" rpy="0 0 0" />
      <geometry>
        <mesh filename="package://ers6_description/meshes/Base.stl" scale="0.001 0.001 0.001" />
      </geometry>
    </collision>
    <inertial>
      <origin xyz="0 0 0" rpy="0 0 0" />
      <mass value="1" />
      <inertia ixx="0.4" ixy="0" ixz="0" iyy="0.4" iyz="0" izz="0.4" />
    </inertial>
  </link>
  <joint name="base_link_to_a5" type="revolute">
    <parent link="base_link" />
    <child link="a5" />
    <origin xyz="0.000060582689466064966 0.0004769508252860928 0.0732228209466252" rpy="0 0 0" />
    <axis xyz="0 0 1"/>
    <limit effort="1000.0" lower="-1" upper="1" velocity="0.5"/>  </joint>
  <link name="a5">
    <visual>
      <origin xyz="0.00024149299047160257 -0.00006662961777630398 -0.003721416044104253" rpy="0 0 0" />
      <geometry>
        <mesh filename="package://ers6_description/meshes/a5.stl" scale="0.001 0.001 0.001" />
      </geometry>
      <material name="a5-material">
        <color rgba="0.22322795730611386 0.14412847084818123 1 1" />
      </material>
    </visual>
    <collision>
      <origin xyz="0.00024149299047160257 -0.00006662961777630398 -0.003721416044104253" rpy="0 0 0" />
      <geometry>
        <mesh filename="package://ers6_description/meshes/a5.stl" scale="0.001 0.001 0.001" />
      </geometry>
    </collision>
    <inertial>
      <origin xyz="0.00024149299047160257 -0.00006662961777630398 -0.003721416044104253" rpy="0 0 0" />
      <mass value="1" />
      <inertia ixx="0.4" ixy="0" ixz="0" iyy="0.4" iyz="0" izz="0.4" />
    </inertial>
  </link>
  <joint name="a5_to_a4" type="revolute">
    <parent link="a5" />
    <child link="a4" />
    <origin xyz="0.16917411790950931 0.00002629570427786776 0.06198128719208244" rpy="0 0 1.5707963267948963" />
    <axis xyz="2.2204424853991772e-16 -0.9999983949841352 -0.001791655422669125"/>
    <limit effort="1000.0" lower="-1" upper="1" velocity="0.5"/>  </joint>
  <link name="a4">
    <visual>
      <origin xyz="0 0 0" rpy="0 0 0" />
      <geometry>
        <mesh filename="package://ers6_description/meshes/a4.stl" scale="0.001 0.001 0.001" />
      </geometry>
      <material name="a4-material">
        <color rgba="0.35640014413537763 0.6583748172725346 0.07421356837213867 1" />
      </material>
    </visual>
    <collision>
      <origin xyz="0 0 0" rpy="0 0 0" />
      <geometry>
        <mesh filename="package://ers6_description/meshes/a4.stl" scale="0.001 0.001 0.001" />
      </geometry>
    </collision>
    <inertial>
      <origin xyz="0 0 0" rpy="0 0 0" />
      <mass value="1" />
      <inertia ixx="0.4" ixy="0" ixz="0" iyy="0.4" iyz="0" izz="0.4" />
    </inertial>
  </link>
  <joint name="a4_to_a3" type="revolute">
    <parent link="a4" />
    <child link="a3" />
    <origin xyz="0 0.1685 0.20" rpy="0 0 3.141592653589793" />
    <axis xyz="2.2204349637747346e-16 -0.9999950075456312 0.0031598866772435397"/>
    <limit effort="1000.0" lower="-1" upper="1" velocity="0.5"/>  </joint>
  <link name="a3">
    <visual>
      <origin xyz="7.399065680067473e-20 0 0.0371754409751881" rpy="0 0 0" />
      <geometry>
        <mesh filename="package://ers6_description/meshes/a3.stl" scale="0.001 0.001 0.001" />
      </geometry>
      <material name="a3-material">
        <color rgba="0.85499260812105 0.04970656597728775 0.04970656597728775 1" />
      </material>
    </visual>
    <collision>
      <origin xyz="7.399065680067473e-20 0 0.0371754409751881" rpy="0 0 0" />
      <geometry>
        <mesh filename="package://ers6_description/meshes/a3.stl" scale="0.001 0.001 0.001" />
      </geometry>
    </collision>
    <inertial>
      <origin xyz="7.399065680067473e-20 0 0.0371754409751881" rpy="0 0 0" />
      <mass value="1" />
      <inertia ixx="0.4" ixy="0" ixz="0" iyy="0.4" iyz="0" izz="0.4" />
    </inertial>
  </link>
  <joint name="a3_to_a2" type="revolute">
    <parent link="a3" />
    <child link="a2" />
    <origin xyz="0.0005014862197909482 -0.0005754625084648142 0.03310193380359011" rpy="0 0 0" />
    <axis xyz="0 0 1"/>
    <limit effort="1000.0" lower="-1" upper="1" velocity="0.5"/>  </joint>
  <link name="a2">
    <visual>
      <origin xyz="-0.015941182779098312 -0.03442337337371612 0" rpy="0 0 0" />
      <geometry>
        <mesh filename="package://ers6_description/meshes/a2.stl" scale="0.001 0.001 0.001" />
      </geometry>
      <material name="a2-material">
        <color rgba="0.6375968739867731 0.6724431569510133 0.8796223968851662 1" />
      </material>
    </visual>
    <collision>
      <origin xyz="-0.015941182779098312 -0.03442337337371612 0" rpy="0 0 0" />
      <geometry>
        <mesh filename="package://ers6_description/meshes/a2.stl" scale="0.001 0.001 0.001" />
      </geometry>
    </collision>
    <inertial>
      <origin xyz="-0.015941182779098312 -0.03442337337371612 0" rpy="0 0 0" />
      <mass value="1" />
      <inertia ixx="0.4" ixy="0" ixz="0" iyy="0.4" iyz="0" izz="0.4" />
    </inertial>
  </link>
  <joint name="a2_to_a1" type="revolute">
    <parent link="a2" />
    <child link="a1" />
    <origin xyz="-0.0004211425734971276 0.00007487255719667088 0.16818515224205283" rpy="0 0 3.141592653589793" />
    <axis xyz="-4.4408551769028203e-16 0.999991685995294 0.004077737153082017"/>
    <limit effort="1000.0" lower="-1" upper="1" velocity="0.5"/>  </joint>
  <link name="a1">
    <visual>
      <origin xyz="-0.00042114257349712755 -0.0005282776510994319 0.024270987241524544" rpy="0 0 0" />
      <geometry>
        <mesh filename="package://ers6_description/meshes/a1.stl" scale="0.001 0.001 0.001" />
      </geometry>
      <material name="a1-material">
        <color rgba="0.19806931954941637 0.4286904966038916 0.015208514418949472 1" />
      </material>
    </visual>
    <collision>
      <origin xyz="-0.00042114257349712755 -0.0005282776510994319 0.024270987241524544" rpy="0 0 0" />
      <geometry>
        <mesh filename="package://ers6_description/meshes/a1.stl" scale="0.001 0.001 0.001" />
      </geometry>
    </collision>
    <inertial>
      <origin xyz="-0.00042114257349712755 -0.0005282776510994319 0.024270987241524544" rpy="0 0 0" />
      <mass value="1" />
      <inertia ixx="0.4" ixy="0" ixz="0" iyy="0.4" iyz="0" izz="0.4" />
    </inertial>
  </link>
  <joint name="a1_to_a0" type="revolute">
    <parent link="a1" />
    <child link="a0" />
    <origin xyz="1.6263032587282567e-19 -0.0003501459947950203 0.02786555015025216" rpy="0 0 -1.5707963267948961" />
    <axis xyz="0 0 1"/>
    <limit effort="1000.0" lower="-1" upper="1" velocity="0.5"/>  </joint>
  <link name="a0">
    <visual>
      <origin xyz="0 0 0" rpy="0 0 0" />
      <geometry>
        <mesh filename="package://ers6_description/meshes/a0.stl" scale="0.001 0.001 0.001" />
      </geometry>
      <material name="a0-material">
        <color rgba="0.3094689228067428 0.0015176349176470587 0.3515325994898463 1" />
      </material>
    </visual>
    <collision>
      <origin xyz="0 0 0" rpy="0 0 0" />
      <geometry>
        <mesh filename="package://ers6_description/meshes/a0.stl" scale="0.001 0.001 0.001" />
      </geometry>
    </collision>
    <inertial>
      <origin xyz="0 0 0" rpy="0 0 0" />
      <mass value="1" />
      <inertia ixx="0.4" ixy="0" ixz="0" iyy="0.4" iyz="0" izz="0.4" />
    </inertial>
  </link>

</robot>